Workbook
Name status: buildReport!$I$3:$I$1000
Name fixVersion: JIRA!$R$2:$R$1000
Name Issue_Type: JIRA!$A$2:$A$1000
Name impact_of_failure: buildReport!$E$3:$E$1000
Name linked_ID: buildReport!$K$3:$K$1000
Name Likelihood_of_failure: buildReport!$F$3:$F$1000
Name jira_priority: JIRA!$D$2:$D$1000
Name issue_ID: JIRA!$B$2:$B$1000
Name release: buildReport!$J$3:$J$1000
Name jira_status: JIRA!$E$2:$E$1000
Name Automation_status: buildReport!$H$3:$H$1000
Name can_be_automated: buildReport!$G$3:$G$1000

Sheet JIRA
A1: Issue Type | B1: Key | C1: Summary | D1: Priority | E1: Status | F1: Created | G1: Linked Issues | H1: Project | I1: Sport | J1: Squad | K1: Components | L1: Test event date | M1: customfield_10436 | N1: customfield_10416 | O1: customfield_10494 | P1: Links | Q1: Status Category Changed | R1: Fix versions | S1: Labels | T1: Software Release | U1: Release date
A2: Bug | B2: =HYPERLINK("https://hawk-eye.atlassian.net/browse/BAS-1354?atlOrigin=eyJpIjoiYzgwYTQ0ZjEyNzQzNGJhN2JmNjEyZTM0NmRhZWZhNjIiLCJwIjoic2hlZXRzLWppcmEifQ","BAS-1354") -> BAS-1354 | C2: NBA are reporting that the last record of `processed.pose.clean` files are truncated. | D2: P3 - Medium | E2: In Progress | F2: 45939.382 | G2: =HYPERLINK("https://hawk-eye.atlassian.net/browse/BAS-1226?atlOrigin=eyJpIjoiYzgwYTQ0ZjEyNzQzNGJhN2JmNjEyZTM0NmRhZWZhNjIiLCJwIjoic2hlZXRzLWppcmEifQ","BAS-1226") -> BAS-1226 | H2: Basketball & Baseball Data Platform | M2: [no field found] | N2: [no field found] | O2: [no field found] | Q2: 45940.467 | S2: Basketball | U2: 45692
A3: Story | B3: =HYPERLINK("https://hawk-eye.atlassian.net/browse/BAS-1353?atlOrigin=eyJpIjoiYzgwYTQ0ZjEyNzQzNGJhN2JmNjEyZTM0NmRhZWZhNjIiLCJwIjoic2hlZXRzLWppcmEifQ","BAS-1353") -> BAS-1353 | C3: Interpret new 'heave' event from NGSS | D3: P3 - Medium | E3: Backlog | F3: 45938.565 | G3: =HYPERLINK("https://hawk-eye.atlassian.net/browse/?atlOrigin=eyJpIjoiYzgwYTQ0ZjEyNzQzNGJhN2JmNjEyZTM0NmRhZWZhNjIiLCJwIjoic2hlZXRzLWppcmEifQ","") | H3: Basketball & Baseball Data Platform | M3: [no field found] | N3: [no field found] | O3: [no field found] | Q3: 45938.565 | S3: Basketball;Feature | U3: 45691
A4: Bug | B4: =HYPERLINK("https://hawk-eye.atlassian.net/browse/BAS-1352?atlOrigin=eyJpIjoiYzgwYTQ0ZjEyNzQzNGJhN2JmNjEyZTM0NmRhZWZhNjIiLCJwIjoic2hlZXRzLWppcmEifQ","BAS-1352") -> BAS-1352 | C4: Live Event feed numbering | D4: P2 - High | E4: Done | F4: 45937.518 | G4: =HYPERLINK("https://hawk-eye.atlassian.net/browse/BAS-1274?atlOrigin=eyJpIjoiYzgwYTQ0ZjEyNzQzNGJhN2JmNjEyZTM0NmRhZWZhNjIiLCJwIjoic2hlZXRzLWppcmEifQ","BAS-1274") -> BAS-1274 | H4: Basketball & Baseball Data Platform | M4: [no field found] | N4: [no field found] | O4: [no field found] | Q4: 45944.6 | R4: 2.42 | S4: Basketball;Feature | T4: 1 | U4: 45658
A5: Story | B5: =HYPERLINK("https://hawk-eye.atlassian.net/browse/BAS-1351?atlOrigin=eyJpIjoiYzgwYTQ0ZjEyNzQzNGJhN2JmNjEyZTM0NmRhZWZhNjIiLCJwIjoic2hlZXRzLWppcmEifQ","BAS-1351") -> BAS-1351 | C5: NBA to Access Status Update API via a Key | D5: P2 - High | E5: Backlog | F5: 45937.457 | G5: =HYPERLINK("https://hawk-eye.atlassian.net/browse/?atlOrigin=eyJpIjoiYzgwYTQ0ZjEyNzQzNGJhN2JmNjEyZTM0NmRhZWZhNjIiLCJwIjoic2hlZXRzLWppcmEifQ","") | H5: Basketball & Baseball Data Platform | M5: [no field found] | N5: [no field found] | O5: [no field found] | Q5: 45937.457 | S5: Basketball;DevOps;Feature | U5: 45667
A6: Bug | B6: =HYPERLINK("https://hawk-eye.atlassian.net/browse/BAS-1344?atlOrigin=eyJpIjoiYzgwYTQ0ZjEyNzQzNGJhN2JmNjEyZTM0NmRhZWZhNjIiLCJwIjoic2hlZXRzLWppcmEifQ","BAS-1344") -> BAS-1344 | C6: SFG cannot authenticate with Dynamo DB in AWS | D6: P1 - Highest | E6: Closed | F6: 45919.617 | G6: =HYPERLINK("https://hawk-eye.atlassian.net/browse/BAS-1226?atlOrigin=eyJpIjoiYzgwYTQ0ZjEyNzQzNGJhN2JmNjEyZTM0NmRhZWZhNjIiLCJwIjoic2hlZXRzLWppcmEifQ","BAS-1226") -> BAS-1226 | H6: Basketball & Baseball Data Platform | M6: [no field found] | N6: [no field found] | O6: [no field found] | Q6: 45924.406 | S6: Basketball;Feature | U6: 45667
A7: Bug | B7: =HYPERLINK("https://hawk-eye.atlassian.net/browse/BAS-1342?atlOrigin=eyJpIjoiYzgwYTQ0ZjEyNzQzNGJhN2JmNjEyZTM0NmRhZWZhNjIiLCJwIjoic2hlZXRzLWppcmEifQ","BAS-1342") -> BAS-1342 | C7: Status Update API updates not showing in DynamoDB | D7: P2 - High | E7: Closed | F7: 45916.744 | G7: =HYPERLINK("https://hawk-eye.atlassian.net/browse/?atlOrigin=eyJpIjoiYzgwYTQ0ZjEyNzQzNGJhN2JmNjEyZTM0NmRhZWZhNjIiLCJwIjoic2hlZXRzLWppcmEifQ","") | H7: Basketball & Baseball Data Platform | M7: [no field found] | N7: [no field found] | O7: [no field found] | Q7: 45924.406 | R7: 2.41 | S7: Basketball;Feature | T7: 1 | U7: 45658
A8: Story | B8: =HYPERLINK("https://hawk-eye.atlassian.net/browse/BAS-1338?atlOrigin=eyJpIjoiYzgwYTQ0ZjEyNzQzNGJhN2JmNjEyZTM0NmRhZWZhNjIiLCJwIjoic2hlZXRzLWppcmEifQ","BAS-1338") -> BAS-1338 | C8: Add Clock Events To Combine Events Feed & Join With NGSS Events | D8: P2 - High | E8: To Test | F8: 45912.153 | G8: =HYPERLINK("https://hawk-eye.atlassian.net/browse/BAS-1337?atlOrigin=eyJpIjoiYzgwYTQ0ZjEyNzQzNGJhN2JmNjEyZTM0NmRhZWZhNjIiLCJwIjoic2hlZXRzLWppcmEifQ","BAS-1337") -> BAS-1337 | H8: Basketball & Baseball Data Platform | M8: [no field found] | N8: [no field found] | O8: [no field found] | Q8: 45923.498 | R8: 2.42 | S8: Basketball;Feature | T8: 1 | U8: 45658
A9: Story | B9: =HYPERLINK("https://hawk-eye.atlassian.net/browse/BAS-1337?atlOrigin=eyJpIjoiYzgwYTQ0ZjEyNzQzNGJhN2JmNjEyZTM0NmRhZWZhNjIiLCJwIjoic2hlZXRzLWppcmEifQ","BAS-1337") -> BAS-1337 | C9: Add Clock Stop/Start Events to Live Events Feed | D9: P2 - High | E9: Closed | F9: 45911.763 | G9: =HYPERLINK("https://hawk-eye.atlassian.net/browse/BAS-1338?atlOrigin=eyJpIjoiYzgwYTQ0ZjEyNzQzNGJhN2JmNjEyZTM0NmRhZWZhNjIiLCJwIjoic2hlZXRzLWppcmEifQ","BAS-1338") -> BAS-1338 | H9: Basketball & Baseball Data Platform | M9: [no field found] | N9: [no field found] | O9: [no field found] | Q9: 45932.588 | R9: 2.41 | S9: Basketball;Feature | T9: 1 | U9: 45662
A10: Story | B10: =HYPERLINK("https://hawk-eye.atlassian.net/browse/BAS-1328?atlOrigin=eyJpIjoiYzgwYTQ0ZjEyNzQzNGJhN2JmNjEyZTM0NmRhZWZhNjIiLCJwIjoic2hlZXRzLWppcmEifQ","BAS-1328") -> BAS-1328 | C10: Starter project for Eden | D10: P5 - Lowest | E10: Backlog | F10: 45909.689 | G10: =HYPERLINK("https://hawk-eye.atlassian.net/browse/?atlOrigin=eyJpIjoiYzgwYTQ0ZjEyNzQzNGJhN2JmNjEyZTM0NmRhZWZhNjIiLCJwIjoic2hlZXRzLWppcmEifQ","") | H10: Basketball & Baseball Data Platform | M10: [no field found] | N10: [no field found] | O10: [no field found] | Q10: 45909.689 | S10: Basketball | U10: 45699
A11: Story | B11: =HYPERLINK("https://hawk-eye.atlassian.net/browse/BAS-1326?atlOrigin=eyJpIjoiYzgwYTQ0ZjEyNzQzNGJhN2JmNjEyZTM0NmRhZWZhNjIiLCJwIjoic2hlZXRzLWppcmEifQ","BAS-1326") -> BAS-1326 | C11: Add Chance To Score data to Officiating Events Feed | D11: P2 - High | E11: To Test | F11: 45901.727 | G11: =HYPERLINK("https://hawk-eye.atlassian.net/browse/?atlOrigin=eyJpIjoiYzgwYTQ0ZjEyNzQzNGJhN2JmNjEyZTM0NmRhZWZhNjIiLCJwIjoic2hlZXRzLWppcmEifQ","") | H11: Basketball & Baseball Data Platform | M11: [no field found] | N11: [no field found] | O11: [no field found] | Q11: 45943.405 | R11: 2.42 | S11: Basketball;Feature | U11: 45735
A12: Story | B12: =HYPERLINK("https://hawk-eye.atlassian.net/browse/BAS-1322?atlOrigin=eyJpIjoiYzgwYTQ0ZjEyNzQzNGJhN2JmNjEyZTM0NmRhZWZhNjIiLCJwIjoic2hlZXRzLWppcmEifQ","BAS-1322") -> BAS-1322 | C12: Allow scopes in the JWT to grant authorisation | D12: P5 - Lowest | E12: Closed | F12: 45897.48 | G12: =HYPERLINK("https://hawk-eye.atlassian.net/browse/?atlOrigin=eyJpIjoiYzgwYTQ0ZjEyNzQzNGJhN2JmNjEyZTM0NmRhZWZhNjIiLCJwIjoic2hlZXRzLWppcmEifQ","") | H12: Basketball & Baseball Data Platform | M12: [no field found] | N12: [no field found] | O12: [no field found] | Q12: 45924.404 | R12: 2.41 | S12: Basketball;Feature | U12: 45667
A13: Bug | B13: =HYPERLINK("https://hawk-eye.atlassian.net/browse/BAS-1321?atlOrigin=eyJpIjoiYzgwYTQ0ZjEyNzQzNGJhN2JmNjEyZTM0NmRhZWZhNjIiLCJwIjoic2hlZXRzLWppcmEifQ","BAS-1321") -> BAS-1321 | C13: Basket centre is not being reporting in processed feeds | D13: P2 - High | E13: Backlog | F13: 45894.707 | G13: =HYPERLINK("https://hawk-eye.atlassian.net/browse/?atlOrigin=eyJpIjoiYzgwYTQ0ZjEyNzQzNGJhN2JmNjEyZTM0NmRhZWZhNjIiLCJwIjoic2hlZXRzLWppcmEifQ","") | H13: Basketball & Baseball Data Platform | M13: [no field found] | N13: [no field found] | O13: [no field found] | Q13: 45894.707 | S13: Basketball;TechDebt | U13: 45667
A14: Story | B14: =HYPERLINK("https://hawk-eye.atlassian.net/browse/BAS-1320?atlOrigin=eyJpIjoiYzgwYTQ0ZjEyNzQzNGJhN2JmNjEyZTM0NmRhZWZhNjIiLCJwIjoic2hlZXRzLWppcmEifQ","BAS-1320") -> BAS-1320 | C14: Add arenaId to OpenAPI Spec | D14: P3 - Medium | E14: Closed | F14: 45889.758 | G14: =HYPERLINK("https://hawk-eye.atlassian.net/browse/BAS-1140?atlOrigin=eyJpIjoiYzgwYTQ0ZjEyNzQzNGJhN2JmNjEyZTM0NmRhZWZhNjIiLCJwIjoic2hlZXRzLWppcmEifQ","BAS-1140") -> BAS-1140 | H14: Basketball & Baseball Data Platform | M14: [no field found] | N14: [no field found] | O14: [no field found] | Q14: 45924.405 | R14: 2.41 | S14: Basketball;Feature | T14: 1 | U14: 45662
A15: Bug | B15: =HYPERLINK("https://hawk-eye.atlassian.net/browse/BAS-1318?atlOrigin=eyJpIjoiYzgwYTQ0ZjEyNzQzNGJhN2JmNjEyZTM0NmRhZWZhNjIiLCJwIjoic2hlZXRzLWppcmEifQ","BAS-1318") -> BAS-1318 | C15: Test Stream 2nd Game taking a long time to start publishing | D15: P3 - Medium | E15: Closed | F15: 45889.466 | G15: =HYPERLINK("https://hawk-eye.atlassian.net/browse/?atlOrigin=eyJpIjoiYzgwYTQ0ZjEyNzQzNGJhN2JmNjEyZTM0NmRhZWZhNjIiLCJwIjoic2hlZXRzLWppcmEifQ","") | H15: Basketball & Baseball Data Platform | M15: [no field found] | N15: [no field found] | O15: [no field found] | Q15: 45897.427 | S15: Basketball | T15: 1 | U15: 45662
A16: Story | B16: =HYPERLINK("https://hawk-eye.atlassian.net/browse/BAS-1316?atlOrigin=eyJpIjoiYzgwYTQ0ZjEyNzQzNGJhN2JmNjEyZTM0NmRhZWZhNjIiLCJwIjoic2hlZXRzLWppcmEifQ","BAS-1316") -> BAS-1316 | C16: Convert radians to degrees | D16: P1 - Highest | E16: Closed | F16: 45888.875 | G16: =HYPERLINK("https://hawk-eye.atlassian.net/browse/BAS-1317?atlOrigin=eyJpIjoiYzgwYTQ0ZjEyNzQzNGJhN2JmNjEyZTM0NmRhZWZhNjIiLCJwIjoic2hlZXRzLWppcmEifQ","BAS-1317") -> BAS-1317 | H16: Basketball & Baseball Data Platform | M16: [no field found] | N16: [no field found] | O16: [no field found] | Q16: 45932.697 | R16: 2.41 | S16: Basketball;Feature;Improvement | U16: 45667
A17: Story | B17: =HYPERLINK("https://hawk-eye.atlassian.net/browse/BAS-1303?atlOrigin=eyJpIjoiYzgwYTQ0ZjEyNzQzNGJhN2JmNjEyZTM0NmRhZWZhNjIiLCJwIjoic2hlZXRzLWppcmEifQ","BAS-1303") -> BAS-1303 | C17: Resend Updated List of 23/24 Games | D17: P3 - Medium | E17: Backlog | F17: 45874.512 | G17: =HYPERLINK("https://hawk-eye.atlassian.net/browse/BAS-1202?atlOrigin=eyJpIjoiYzgwYTQ0ZjEyNzQzNGJhN2JmNjEyZTM0NmRhZWZhNjIiLCJwIjoic2hlZXRzLWppcmEifQ","BAS-1202") -> BAS-1202 | H17: Basketball & Baseball Data Platform | M17: [no field found] | N17: [no field found] | O17: [no field found] | Q17: 45874.512 | S17: Basketball;CustomerRaised;Feature | U17: 45667
A18: Story | B18: =HYPERLINK("https://hawk-eye.atlassian.net/browse/BAS-1301?atlOrigin=eyJpIjoiYzgwYTQ0ZjEyNzQzNGJhN2JmNjEyZTM0NmRhZWZhNjIiLCJwIjoic2hlZXRzLWppcmEifQ","BAS-1301") -> BAS-1301 | C18: Cater for ReboundDeflection Event | D18: P2 - High | E18: Closed | F18: 45874.504 | G18: =HYPERLINK("https://hawk-eye.atlassian.net/browse/RTT-11010?atlOrigin=eyJpIjoiYzgwYTQ0ZjEyNzQzNGJhN2JmNjEyZTM0NmRhZWZhNjIiLCJwIjoic2hlZXRzLWppcmEifQ","RTT-11010") -> RTT-11010 | H18: Basketball & Baseball Data Platform | M18: [no field found] | N18: [no field found] | O18: [no field found] | Q18: 45937.416 | R18: 2.41 | S18: Basketball;Feature | U18: 45667
A19: Bug | B19: =HYPERLINK("https://hawk-eye.atlassian.net/browse/BAS-1299?atlOrigin=eyJpIjoiYzgwYTQ0ZjEyNzQzNGJhN2JmNjEyZTM0NmRhZWZhNjIiLCJwIjoic2hlZXRzLWppcmEifQ","BAS-1299") -> BAS-1299 | C19: Repush required radio button cannot be deselected | D19: P5 - Lowest | E19: Backlog | F19: 45873.336 | G19: =HYPERLINK("https://hawk-eye.atlassian.net/browse/BAS-1054?atlOrigin=eyJpIjoiYzgwYTQ0ZjEyNzQzNGJhN2JmNjEyZTM0NmRhZWZhNjIiLCJwIjoic2hlZXRzLWppcmEifQ","BAS-1054") -> BAS-1054 | H19: Basketball & Baseball Data Platform | M19: [no field found] | N19: [no field found] | O19: [no field found] | Q19: 45873.336 | S19: Basketball;Feature;Frontend | U19: 45667
A20: Story | B20: =HYPERLINK("https://hawk-eye.atlassian.net/browse/BAS-1297?atlOrigin=eyJpIjoiYzgwYTQ0ZjEyNzQzNGJhN2JmNjEyZTM0NmRhZWZhNjIiLCJwIjoic2hlZXRzLWppcmEifQ","BAS-1297") -> BAS-1297 | C20: update cors configuration in status update api | D20: P5 - Lowest | E20: Closed | F20: 45868.622 | G20: =HYPERLINK("https://hawk-eye.atlassian.net/browse/?atlOrigin=eyJpIjoiYzgwYTQ0ZjEyNzQzNGJhN2JmNjEyZTM0NmRhZWZhNjIiLCJwIjoic2hlZXRzLWppcmEifQ","") | H20: Basketball & Baseball Data Platform | M20: [no field found] | N20: [no field found] | O20: [no field found] | Q20: 45912.496 | R20: 2.41 | S20: Basketball | U20: 45667
A21: Story | B21: =HYPERLINK("https://hawk-eye.atlassian.net/browse/BAS-1294?atlOrigin=eyJpIjoiYzgwYTQ0ZjEyNzQzNGJhN2JmNjEyZTM0NmRhZWZhNjIiLCJwIjoic2hlZXRzLWppcmEifQ","BAS-1294") -> BAS-1294 | C21: Add Team Logos | D21: P3 - Medium | E21: Closed | F21: 45868.545 | G21: =HYPERLINK("https://hawk-eye.atlassian.net/browse/?atlOrigin=eyJpIjoiYzgwYTQ0ZjEyNzQzNGJhN2JmNjEyZTM0NmRhZWZhNjIiLCJwIjoic2hlZXRzLWppcmEifQ","") | H21: Basketball & Baseball Data Platform | M21: [no field found] | N21: [no field found] | O21: [no field found] | Q21: 45884.446 | R21: 2.41 FE | S21: Basketball;Feature;Frontend | U21: 45667
A22: Story | B22: =HYPERLINK("https://hawk-eye.atlassian.net/browse/BAS-1285?atlOrigin=eyJpIjoiYzgwYTQ0ZjEyNzQzNGJhN2JmNjEyZTM0NmRhZWZhNjIiLCJwIjoic2hlZXRzLWppcmEifQ","BAS-1285") -> BAS-1285 | C22: Upgrade BskDP Spring Boot Version | D22: P5 - Lowest | E22: In Review | F22: 45866.485 | G22: =HYPERLINK("https://hawk-eye.atlassian.net/browse/?atlOrigin=eyJpIjoiYzgwYTQ0ZjEyNzQzNGJhN2JmNjEyZTM0NmRhZWZhNjIiLCJwIjoic2hlZXRzLWppcmEifQ","") | H22: Basketball & Baseball Data Platform | M22: [no field found] | N22: [no field found] | O22: [no field found] | Q22: 45903.618 | S22: Basketball | U22: 45667
A23: Bug | B23: =HYPERLINK("https://hawk-eye.atlassian.net/browse/BAS-1277?atlOrigin=eyJpIjoiYzgwYTQ0ZjEyNzQzNGJhN2JmNjEyZTM0NmRhZWZhNjIiLCJwIjoic2hlZXRzLWppcmEifQ","BAS-1277") -> BAS-1277 | C23: AWS Region not set correctly for SFG & LFG | D23: P2 - High | E23: Closed | F23: 45862.617 | G23: =HYPERLINK("https://hawk-eye.atlassian.net/browse/?atlOrigin=eyJpIjoiYzgwYTQ0ZjEyNzQzNGJhN2JmNjEyZTM0NmRhZWZhNjIiLCJwIjoic2hlZXRzLWppcmEifQ","") | H23: Basketball & Baseball Data Platform | M23: [no field found] | N23: [no field found] | O23: [no field found] | Q23: 45937.697 | S23: Basketball;DevOps | U23: 45691
A24: Story | B24: =HYPERLINK("https://hawk-eye.atlassian.net/browse/BAS-1276?atlOrigin=eyJpIjoiYzgwYTQ0ZjEyNzQzNGJhN2JmNjEyZTM0NmRhZWZhNjIiLCJwIjoic2hlZXRzLWppcmEifQ","BAS-1276") -> BAS-1276 | C24: PMEG rebound logic not behaving the same as LFG | D24: P5 - Lowest | E24: To Test | F24: 45862.453 | G24: =HYPERLINK("https://hawk-eye.atlassian.net/browse/BAS-1174?atlOrigin=eyJpIjoiYzgwYTQ0ZjEyNzQzNGJhN2JmNjEyZTM0NmRhZWZhNjIiLCJwIjoic2hlZXRzLWppcmEifQ","BAS-1174") -> BAS-1174 | H24: Basketball & Baseball Data Platform | M24: [no field found] | N24: [no field found] | O24: [no field found] | Q24: 45937.426 | R24: 2.41 | S24: Basketball;Improvement | U24: 45691
A25: Story | B25: =HYPERLINK("https://hawk-eye.atlassian.net/browse/BAS-1275?atlOrigin=eyJpIjoiYzgwYTQ0ZjEyNzQzNGJhN2JmNjEyZTM0NmRhZWZhNjIiLCJwIjoic2hlZXRzLWppcmEifQ","BAS-1275") -> BAS-1275 | C25: Output backboard touches to the Officiating Events feed | D25: P1 - Highest | E25: Closed | F25: 45861.88 | G25: =HYPERLINK("https://hawk-eye.atlassian.net/browse/?atlOrigin=eyJpIjoiYzgwYTQ0ZjEyNzQzNGJhN2JmNjEyZTM0NmRhZWZhNjIiLCJwIjoic2hlZXRzLWppcmEifQ","") | H25: Basketball & Baseball Data Platform | M25: [no field found] | N25: [no field found] | O25: [no field found] | Q25: 45932.7 | R25: 2.41 | S25: Basketball;Feature | U25: 45672
A26: Story | B26: =HYPERLINK("https://hawk-eye.atlassian.net/browse/BAS-1274?atlOrigin=eyJpIjoiYzgwYTQ0ZjEyNzQzNGJhN2JmNjEyZTM0NmRhZWZhNjIiLCJwIjoic2hlZXRzLWppcmEifQ","BAS-1274") -> BAS-1274 | C26: Ignore new events for the Live Events feed | D26: P2 - High | E26: Closed | F26: 45861.87 | G26: =HYPERLINK("https://hawk-eye.atlassian.net/browse/BAS-1352?atlOrigin=eyJpIjoiYzgwYTQ0ZjEyNzQzNGJhN2JmNjEyZTM0NmRhZWZhNjIiLCJwIjoic2hlZXRzLWppcmEifQ","BAS-1352") -> BAS-1352 | H26: Basketball & Baseball Data Platform | M26: [no field found] | N26: [no field found] | O26: [no field found] | Q26: 45931.732 | R26: 2.41 | S26: Basketball;Feature | U26: 45691
A27: Story | B27: =HYPERLINK("https://hawk-eye.atlassian.net/browse/BAS-1272?atlOrigin=eyJpIjoiYzgwYTQ0ZjEyNzQzNGJhN2JmNjEyZTM0NmRhZWZhNjIiLCJwIjoic2hlZXRzLWppcmEifQ","BAS-1272") -> BAS-1272 | C27: Change test stream games | D27: P3 - Medium | E27: Closed | F27: 45861.839 | G27: =HYPERLINK("https://hawk-eye.atlassian.net/issues/?atlOrigin=eyJpIjoiYzgwYTQ0ZjEyNzQzNGJhN2JmNjEyZTM0NmRhZWZhNjIiLCJwIjoic2hlZXRzLWppcmEifQ&jql=key+in+%28BAS-1189%2CDEVOPS-1004%2CBAS-1314%29","BAS-1189;DEVOPS-1004;BAS-1314") -> BAS-1189;DEVOPS-1004;BAS-1314 | H27: Basketball & Baseball Data Platform | M27: [no field found] | N27: [no field found] | O27: [no field found] | Q27: 45897.426 | S27: Basketball;CustomerRaised | U27: 45672
A28: Story | B28: =HYPERLINK("https://hawk-eye.atlassian.net/browse/BAS-1249?atlOrigin=eyJpIjoiYzgwYTQ0ZjEyNzQzNGJhN2JmNjEyZTM0NmRhZWZhNjIiLCJwIjoic2hlZXRzLWppcmEifQ","BAS-1249") -> BAS-1249 | C28: Add ball spin to Officiating and Live feeds | D28: P2 - High | E28: Closed | F28: 45855.667 | G28: =HYPERLINK("https://hawk-eye.atlassian.net/issues/?atlOrigin=eyJpIjoiYzgwYTQ0ZjEyNzQzNGJhN2JmNjEyZTM0NmRhZWZhNjIiLCJwIjoic2hlZXRzLWppcmEifQ&jql=key+in+%28BAS-742%2CBAS-1345%29","BAS-742;BAS-1345") -> BAS-742;BAS-1345 | H28: Basketball & Baseball Data Platform | M28: [no field found] | N28: [no field found] | O28: [no field found] | Q28: 45860.463 | S28: Basketball | U28: 45672
A29: Story | B29: =HYPERLINK("https://hawk-eye.atlassian.net/browse/BAS-1227?atlOrigin=eyJpIjoiYzgwYTQ0ZjEyNzQzNGJhN2JmNjEyZTM0NmRhZWZhNjIiLCJwIjoic2hlZXRzLWppcmEifQ","BAS-1227") -> BAS-1227 | C29: Lambda for PMEG data to NBA S3 | D29: P3 - Medium | E29: Closed | F29: 45831.007 | G29: =HYPERLINK("https://hawk-eye.atlassian.net/browse/?atlOrigin=eyJpIjoiYzgwYTQ0ZjEyNzQzNGJhN2JmNjEyZTM0NmRhZWZhNjIiLCJwIjoic2hlZXRzLWppcmEifQ","") | H29: Basketball & Baseball Data Platform | M29: [no field found] | N29: [no field found] | O29: [no field found] | Q29: 45860.76 | S29: Basketball;Feature | U29: 45672
A30: Story | B30: =HYPERLINK("https://hawk-eye.atlassian.net/browse/BAS-1226?atlOrigin=eyJpIjoiYzgwYTQ0ZjEyNzQzNGJhN2JmNjEyZTM0NmRhZWZhNjIiLCJwIjoic2hlZXRzLWppcmEifQ","BAS-1226") -> BAS-1226 | C30: Write lambdas to copy over processed data to NBA S3 | D30: P1 - Highest | E30: Closed | F30: 45831.002 | G30: =HYPERLINK("https://hawk-eye.atlassian.net/issues/?atlOrigin=eyJpIjoiYzgwYTQ0ZjEyNzQzNGJhN2JmNjEyZTM0NmRhZWZhNjIiLCJwIjoic2hlZXRzLWppcmEifQ&jql=key+in+%28BAS-1034%2CBAS-1228%2CBAS-1327%2CBAS-1344%2CBAS-1346%2CBAS-1354%29","BAS-1034;BAS-1228;BAS-1327;BAS-1344;BAS-1346;BAS-1354") -> BAS-1034;BAS-1228;BAS-1327;BAS-1344;BAS-1346;BAS-1354 | H30: Basketball & Baseball Data Platform | M30: [no field found] | N30: [no field found] | O30: [no field found] | Q30: 45922.494 | R30: 2.41 | S30: Basketball;Feature | U30: 45672
A31: Story | B31: =HYPERLINK("https://hawk-eye.atlassian.net/browse/BAS-1224?atlOrigin=eyJpIjoiYzgwYTQ0ZjEyNzQzNGJhN2JmNjEyZTM0NmRhZWZhNjIiLCJwIjoic2hlZXRzLWppcmEifQ","BAS-1224") -> BAS-1224 | C31: Use 404 not found responses for status update api | D31: P5 - Lowest | E31: Closed | F31: 45827.469 | G31: =HYPERLINK("https://hawk-eye.atlassian.net/browse/?atlOrigin=eyJpIjoiYzgwYTQ0ZjEyNzQzNGJhN2JmNjEyZTM0NmRhZWZhNjIiLCJwIjoic2hlZXRzLWppcmEifQ","") | H31: Basketball & Baseball Data Platform | M31: [no field found] | N31: [no field found] | O31: [no field found] | Q31: 45860.582 | R31: 2.41 | S31: Basketball;Feature | T31: 1 | U31: 45665
A32: Bug | B32: =HYPERLINK("https://hawk-eye.atlassian.net/browse/BAS-1219?atlOrigin=eyJpIjoiYzgwYTQ0ZjEyNzQzNGJhN2JmNjEyZTM0NmRhZWZhNjIiLCJwIjoic2hlZXRzLWppcmEifQ","BAS-1219") -> BAS-1219 | C32: Error group not removed when user selects clear all. | D32: P5 - Lowest | E32: Closed | F32: 45825.35 | G32: =HYPERLINK("https://hawk-eye.atlassian.net/browse/BAS-1054?atlOrigin=eyJpIjoiYzgwYTQ0ZjEyNzQzNGJhN2JmNjEyZTM0NmRhZWZhNjIiLCJwIjoic2hlZXRzLWppcmEifQ","BAS-1054") -> BAS-1054 | H32: Basketball & Baseball Data Platform | M32: [no field found] | N32: [no field found] | O32: [no field found] | Q32: 45869.327 | R32: 2.41 FE | S32: Basketball;Feature | T32: 2.37 | U32: 45741
A33: Story | B33: =HYPERLINK("https://hawk-eye.atlassian.net/browse/BAS-1204?atlOrigin=eyJpIjoiYzgwYTQ0ZjEyNzQzNGJhN2JmNjEyZTM0NmRhZWZhNjIiLCJwIjoic2hlZXRzLWppcmEifQ","BAS-1204") -> BAS-1204 | C33: Extricate Test Stream from Release Process | D33: P3 - Medium | E33: Backlog | F33: 45819.465 | G33: =HYPERLINK("https://hawk-eye.atlassian.net/browse/BAS-1189?atlOrigin=eyJpIjoiYzgwYTQ0ZjEyNzQzNGJhN2JmNjEyZTM0NmRhZWZhNjIiLCJwIjoic2hlZXRzLWppcmEifQ","BAS-1189") -> BAS-1189 | H33: Basketball & Baseball Data Platform | M33: [no field found] | N33: [no field found] | O33: [no field found] | Q33: 45819.465 | S33: Basketball;TechDebt | U33: 45672
A34: Bug | B34: =HYPERLINK("https://hawk-eye.atlassian.net/browse/BAS-1186?atlOrigin=eyJpIjoiYzgwYTQ0ZjEyNzQzNGJhN2JmNjEyZTM0NmRhZWZhNjIiLCJwIjoic2hlZXRzLWppcmEifQ","BAS-1186") -> BAS-1186 | C34: NGSS data is not saving to S3 in prod | D34: P4 - Low | E34: Backlog | F34: 45814.614 | G34: =HYPERLINK("https://hawk-eye.atlassian.net/browse/BAS-1070?atlOrigin=eyJpIjoiYzgwYTQ0ZjEyNzQzNGJhN2JmNjEyZTM0NmRhZWZhNjIiLCJwIjoic2hlZXRzLWppcmEifQ","BAS-1070") -> BAS-1070 | H34: Basketball & Baseball Data Platform | M34: [no field found] | N34: [no field found] | O34: [no field found] | Q34: 45814.614 | S34: Basketball;Improvement | U34: 45672
A35: Story | B35: =HYPERLINK("https://hawk-eye.atlassian.net/browse/BAS-1178?atlOrigin=eyJpIjoiYzgwYTQ0ZjEyNzQzNGJhN2JmNjEyZTM0NmRhZWZhNjIiLCJwIjoic2hlZXRzLWppcmEifQ","BAS-1178") -> BAS-1178 | C35: Nearest frame time for post process events | D35: P4 - Low | E35: Backlog | F35: 45810.139 | G35: =HYPERLINK("https://hawk-eye.atlassian.net/browse/BAS-561?atlOrigin=eyJpIjoiYzgwYTQ0ZjEyNzQzNGJhN2JmNjEyZTM0NmRhZWZhNjIiLCJwIjoic2hlZXRzLWppcmEifQ","BAS-561") -> BAS-561 | H35: Basketball & Baseball Data Platform | M35: [no field found] | N35: [no field found] | O35: [no field found] | Q35: 45810.139 | S35: Basketball | U35: 45672
A36: Bug | B36: =HYPERLINK("https://hawk-eye.atlassian.net/browse/BAS-1177?atlOrigin=eyJpIjoiYzgwYTQ0ZjEyNzQzNGJhN2JmNjEyZTM0NmRhZWZhNjIiLCJwIjoic2hlZXRzLWppcmEifQ","BAS-1177") -> BAS-1177 | C36: Rebounds from NGSS are being removed from PGCE | D36: P2 - High | E36: Closed | F36: 45810.13 | G36: =HYPERLINK("https://hawk-eye.atlassian.net/issues/?atlOrigin=eyJpIjoiYzgwYTQ0ZjEyNzQzNGJhN2JmNjEyZTM0NmRhZWZhNjIiLCJwIjoic2hlZXRzLWppcmEifQ&jql=key+in+%28BAS-1174%2CBAS-1176%29","BAS-1174;BAS-1176") -> BAS-1174;BAS-1176 | H36: Basketball & Baseball Data Platform | M36: [no field found] | N36: [no field found] | O36: [no field found] | Q36: 45853.59 | S36: Basketball | U36: 45672
A37: Story | B37: =HYPERLINK("https://hawk-eye.atlassian.net/browse/BAS-1175?atlOrigin=eyJpIjoiYzgwYTQ0ZjEyNzQzNGJhN2JmNjEyZTM0NmRhZWZhNjIiLCJwIjoic2hlZXRzLWppcmEifQ","BAS-1175") -> BAS-1175 | C37: Use gameClockRunning field in index file to better filter for pose backfilling | D37: P3 - Medium | E37: Closed | F37: 45810.091 | G37: =HYPERLINK("https://hawk-eye.atlassian.net/browse/BAS-1173?atlOrigin=eyJpIjoiYzgwYTQ0ZjEyNzQzNGJhN2JmNjEyZTM0NmRhZWZhNjIiLCJwIjoic2hlZXRzLWppcmEifQ","BAS-1173") -> BAS-1173 | H37: Basketball & Baseball Data Platform | M37: [no field found] | N37: [no field found] | O37: [no field found] | Q37: 45931.67 | R37: 2.41 | S37: Basketball;Improvement | U37: 45672
A38: Bug | B38: =HYPERLINK("https://hawk-eye.atlassian.net/browse/BAS-1172?atlOrigin=eyJpIjoiYzgwYTQ0ZjEyNzQzNGJhN2JmNjEyZTM0NmRhZWZhNjIiLCJwIjoic2hlZXRzLWppcmEifQ","BAS-1172") -> BAS-1172 | C38: Rework using dribbles to match shots | D38: P3 - Medium | E38: Backlog | F38: 45807.671 | G38: =HYPERLINK("https://hawk-eye.atlassian.net/issues/?atlOrigin=eyJpIjoiYzgwYTQ0ZjEyNzQzNGJhN2JmNjEyZTM0NmRhZWZhNjIiLCJwIjoic2hlZXRzLWppcmEifQ&jql=key+in+%28BAS-714%2CBAS-627%2CBAS-1136%2CBAS-1074%2CBAS-1176%29","BAS-714;BAS-627;BAS-1136;BAS-1074;BAS-1176") -> BAS-714;BAS-627;BAS-1136;BAS-1074;BAS-1176 | H38: Basketball & Baseball Data Platform | M38: [no field found] | N38: [no field found] | O38: [no field found] | Q38: 45807.671 | S38: Basketball;Improvement | U38: 45672
A39: Story | B39: =HYPERLINK("https://hawk-eye.atlassian.net/browse/BAS-1166?atlOrigin=eyJpIjoiYzgwYTQ0ZjEyNzQzNGJhN2JmNjEyZTM0NmRhZWZhNjIiLCJwIjoic2hlZXRzLWppcmEifQ","BAS-1166") -> BAS-1166 | C39: Build TimeInput Component | D39: P3 - Medium | E39: Closed | F39: 45804.534 | G39: =HYPERLINK("https://hawk-eye.atlassian.net/browse/?atlOrigin=eyJpIjoiYzgwYTQ0ZjEyNzQzNGJhN2JmNjEyZTM0NmRhZWZhNjIiLCJwIjoic2hlZXRzLWppcmEifQ","") | H39: Basketball & Baseball Data Platform | M39: [no field found] | N39: [no field found] | O39: [no field found] | Q39: 45926.426 | R39: 2.41 FE | S39: Basketball;Feature;Frontend | U39: 45672
A40: Story | B40: =HYPERLINK("https://hawk-eye.atlassian.net/browse/BAS-1165?atlOrigin=eyJpIjoiYzgwYTQ0ZjEyNzQzNGJhN2JmNjEyZTM0NmRhZWZhNjIiLCJwIjoic2hlZXRzLWppcmEifQ","BAS-1165") -> BAS-1165 | C40: Build SelectPill Component | D40: P3 - Medium | E40: Closed | F40: 45804.514 | G40: =HYPERLINK("https://hawk-eye.atlassian.net/browse/?atlOrigin=eyJpIjoiYzgwYTQ0ZjEyNzQzNGJhN2JmNjEyZTM0NmRhZWZhNjIiLCJwIjoic2hlZXRzLWppcmEifQ","") | H40: Basketball & Baseball Data Platform | M40: [no field found] | N40: [no field found] | O40: [no field found] | Q40: 45876.712 | R40: 2.41 FE | S40: Basketball;Feature;Frontend | U40: 45672
...

Sheet ProjectHealth
B2: Basketball Data platform | F2: release | G2: 2.41 FE
B3: As at
B4: =now() -> 46053.434
B5: Project Health | E5: release readiness
B6: =IF(COUNTIF(F7:G7,"Red")>0,"Red",if(COUNTIF(F7:G7,"Amber")>0,"Amber","Green")) -> Green | E6: Automation | F6: test execution | G6: bugs raised | H6: tech debt
E7: =IF(COUNTIF(N22:P24,"Red")>0,"Red",if(COUNTIF(N22:P24,"Amber")>0,"Amber","Green")) -> Red | F7: =IF(COUNTIF(N30:P32,"Red")>0,"Red",if(COUNTIF(N30:P32,"Amber")>0,"Amber","Green")) -> Green | G7: =IF(COUNTIF(J16,"Red")>0,"Red",if(COUNTIF(J16,"Amber")>0,"Amber","Green")) -> Green | H7: =COUNTIF(JIRA!E:E, "In Review")+COUNTIF(JIRA!E:E, "Backlog")+COUNTIF(JIRA!E:E, "On Hold)") -> 55
B10: Risk profile counts | D10: Release | I10: open bugs | J10: Release
D11: Impact of failure | I11: P1 - Highest | J11: =IF($J$10="Release",COUNTIFS(Issue_Type,"Bug",jira_priority,I11,jira_status,"<>Closed",jira_status,"<>Done",fixVersion,$G$2),COUNTIFS(Issue_Type,"Bug",jira_priority,I11,jira_status,"<>Closed",jira_status,"<>Done")) -> 0
D12: Minor | E12: Visible | F12: Interruption | G12: Total | I12: P2 - High | J12: =IF($J$10="Release",COUNTIFS(Issue_Type,"Bug",jira_priority,I12,jira_status,"<>Closed",jira_status,"<>Done",fixVersion,$G$2),COUNTIFS(Issue_Type,"Bug",jira_priority,I12,jira_status,"<>Closed",jira_status,"<>Done")) -> 0
B13: Likelihood of failure | C13: Very likely | D13: =IF(D10="Release",COUNTIFS(impact_of_failure,3,Likelihood_of_failure,1,release,G2),COUNTIFS(impact_of_failure,3,Likelihood_of_failure,1)) -> 0 | E13: =if(D10="Release",COUNTIFS(impact_of_failure,2,Likelihood_of_failure,1,release,G2),COUNTIFS(impact_of_failure,2,Likelihood_of_failure,1)) -> 0 | F13: =IF(D10="Release",COUNTIFS(impact_of_failure,1,Likelihood_of_failure,1,release,G2),COUNTIFS(impact_of_failure,1,Likelihood_of_failure,1)) -> 0 | G13: =SUM(D13:F13) -> 0 | I13: P3 - Medium | J13: =IF($J$10="Release",COUNTIFS(Issue_Type,"Bug",jira_priority,I13,jira_status,"<>Closed",jira_status,"<>Done",fixVersion,$G$2),COUNTIFS(Issue_Type,"Bug",jira_priority,I13,jira_status,"<>Closed",jira_status,"<>Done")) -> 0
C14: Quite likely | D14: =IF(D10="Release",COUNTIFS(impact_of_failure,3,Likelihood_of_failure,2,release,G2),COUNTIFS(impact_of_failure,3,Likelihood_of_failure,2)) -> 0 | E14: =IF(D10="Release",COUNTIFS(impact_of_failure,2,Likelihood_of_failure,2,release,G2),COUNTIFS(impact_of_failure,2,Likelihood_of_failure,2)) -> 0 | F14: =IF(D10="Release",COUNTIFS(impact_of_failure,1,Likelihood_of_failure,2,release,G2),COUNTIFS(impact_of_failure,1,Likelihood_of_failure,2)) -> 0 | G14: =SUM(D14:F14) -> 0 | I14: P4 - Low | J14: =IF($J$10="Release",COUNTIFS(Issue_Type,"Bug",jira_priority,I14,jira_status,"<>Closed",jira_status,"<>Done",fixVersion,$G$2),COUNTIFS(Issue_Type,"Bug",jira_priority,I14,jira_status,"<>Closed",jira_status,"<>Done")) -> 0
C15: Unlikely | D15: =IF(D10="Release",COUNTIFS(impact_of_failure,3,Likelihood_of_failure,3,release,G2),COUNTIFS(impact_of_failure,3,Likelihood_of_failure,3)) -> 0 | E15: =IF(D10="Release",COUNTIFS(impact_of_failure,2,Likelihood_of_failure,3,release,G2),COUNTIFS(impact_of_failure,2,Likelihood_of_failure,3)) -> 0 | F15: =IF(D10="Release",COUNTIFS(impact_of_failure,1,Likelihood_of_failure,3,release,G2),COUNTIFS(impact_of_failure,1,Likelihood_of_failure,3)) -> 0 | G15: =SUM(D15:F15) -> 0 | I15: P5 - Lowest | J15: =IF($J$10="Release",COUNTIFS(Issue_Type,"Bug",jira_priority,I15,jira_status,"<>Closed",jira_status,"<>Done",fixVersion,$G$2),COUNTIFS(Issue_Type,"Bug",jira_priority,I15,jira_status,"<>Closed",jira_status,"<>Done")) -> 0
C16: Total | D16: =SUM(D13:D15) -> 0 | E16: =SUM(E13:E15) -> 0 | F16: =SUM(F13:F15) -> 0 | G16: =SUM(G13:G15) -> 0 | I16: Status | J16: =IF(or(J11>0,J12>0),"Red",if(J13>0,"Amber","Green")) -> Green
B20: Automation coverage | D20: Project
C21: Minor | D21: Visible | E21: Interruption | F21: Total | I21: Minor | J21: Visible | K21: Interruption | N21: Minor | O21: Visible | P21: Interruption
B22: Very likely | C22: =IF(D20="Release",COUNTIFS(impact_of_failure,3,Likelihood_of_failure,1,can_be_automated,"Yes",release,H7),COUNTIFS(impact_of_failure,3,Likelihood_of_failure,1,can_be_automated,"Yes")) -> 1 | D22: =IF(D20="Release",COUNTIFS(impact_of_failure,2,Likelihood_of_failure,1,can_be_automated,"Yes",release,G2),COUNTIFS(impact_of_failure,2,Likelihood_of_failure,1,can_be_automated,"Yes")) -> 7 | E22: =IF(D20="Release",COUNTIFS(impact_of_failure,1,Likelihood_of_failure,1,can_be_automated,"Yes",release,G2),COUNTIFS(impact_of_failure,1,Likelihood_of_failure,1,can_be_automated,"Yes")) -> 14 | F22: =SUM(C22:E22) -> 22 | H22: Very likely | I22: =IFERROR(if(D20="Release",COUNTIFS(impact_of_failure,3,Likelihood_of_failure,1,Automation_status,"Yes",release,G2),COUNTIFS(impact_of_failure,3,Likelihood_of_failure,1,Automation_status,"Yes"))/C22,1) -> 1 | J22: =IFERROR(if(D20="Release",COUNTIFS(impact_of_failure,2,Likelihood_of_failure,1,Automation_status,"Yes",release,G2),COUNTIFS(impact_of_failure,2,Likelihood_of_failure,1,Automation_status,"Yes"))/D22,1) -> 0.28571429 | K22: =IFERROR(if(D20="Release",COUNTIFS(impact_of_failure,1,Likelihood_of_failure,1,Automation_status,"Yes",release,G2),COUNTIFS(impact_of_failure,1,Likelihood_of_failure,1,Automation_status,"Yes"))/E22,1) -> 0.071428571 | M22: Very likely | N22: =if(instructions!C$4=0,"Green",if(I22<instructions!H$4,"Red",if(AND(I22>=instructions!H$4,I22<instructions!C$4),"Amber","Green"))) -> Green | O22: =if(instructions!D4=0,"Green",if(J22<instructions!I4,"Red",if(AND(J22>=instructions!I4,J22<instructions!D4),"Amber","Green"))) -> Amber | P22: =if(instructions!E4=0,"Green",if(K22<instructions!J4,"Red",if(AND(K22>=instructions!J4,K22<instructions!E4),"Amber","Green"))) -> Red
B23: Quite likely | C23: =IF(D20="Release",COUNTIFS(impact_of_failure,3,Likelihood_of_failure,2,can_be_automated,"Yes",release,G2),COUNTIFS(impact_of_failure,3,Likelihood_of_failure,2,can_be_automated,"Yes")) -> 5 | D23: =IF(D20="Release",COUNTIFS(impact_of_failure,2,Likelihood_of_failure,2,can_be_automated,"Yes",release,G2),COUNTIFS(impact_of_failure,2,Likelihood_of_failure,2,can_be_automated,"Yes")) -> 20 | E23: =IF(D20="Release",COUNTIFS(impact_of_failure,1,Likelihood_of_failure,2,can_be_automated,"Yes",release,G2),COUNTIFS(impact_of_failure,1,Likelihood_of_failure,2,can_be_automated,"Yes")) -> 28 | F23: =SUM(C23:E23) -> 53 | H23: Quite likely | I23: =IFERROR(if(D20="Release",COUNTIFS(impact_of_failure,3,Likelihood_of_failure,2,Automation_status,"Yes",release,G2),COUNTIFS(impact_of_failure,3,Likelihood_of_failure,2,Automation_status,"Yes"))/C23,1) -> 0 | J23: =IFERROR(if(D20="Release", COUNTIFS(impact_of_failure,2,Likelihood_of_failure,2,Automation_status,"Yes",release,G2),COUNTIFS(impact_of_failure,2,Likelihood_of_failure,2,Automation_status,"Yes"))/D23,1) -> 0.15 | K23: =IFERROR(if(D20="Release",COUNTIFS(impact_of_failure,1,Likelihood_of_failure,2,Automation_status,"Yes",release,G2),COUNTIFS(impact_of_failure,1,Likelihood_of_failure,2,Automation_status,"Yes"))/E23,1) -> 0.21428571 | M23: Quite likely | N23: =if(instructions!C5=0,"Green",if(I23<instructions!H5,"Red",if(AND(I23>=instructions!H5,I23<instructions!C5),"Amber","Green"))) -> Green | O23: =if(instructions!D5=0,"Green",if(J23<instructions!I5,"Red",if(AND(J23>=instructions!I5,J23<instructions!D5),"Amber","Green"))) -> Amber | P23: =if(instructions!E5=0,"Green",if(K23<instructions!J5,"Red",if(AND(K23>=instructions!J5,K23<instructions!E5),"Amber","Green"))) -> Red
B24: Unlikely | C24: =IF(D20="Release",COUNTIFS(impact_of_failure,3,Likelihood_of_failure,3,can_be_automated,"Yes",release,G2),COUNTIFS(impact_of_failure,3,Likelihood_of_failure,3,can_be_automated,"Yes")) -> 4 | D24: =IF(D20="Release",COUNTIFS(impact_of_failure,2,Likelihood_of_failure,3,can_be_automated,"Yes",release,G2),COUNTIFS(impact_of_failure,2,Likelihood_of_failure,3,can_be_automated,"Yes")) -> 15 | E24: =IF(D20="Release",COUNTIFS(impact_of_failure,1,Likelihood_of_failure,3,can_be_automated,"Yes",release,G2),COUNTIFS(impact_of_failure,1,Likelihood_of_failure,3,can_be_automated,"Yes")) -> 13 | F24: =SUM(C24:E24) -> 32 | H24: Unlikely | I24: =IFERROR(if(D20="Release", COUNTIFS(impact_of_failure,3,Likelihood_of_failure,3,Automation_status,"Yes",release,G2),COUNTIFS(impact_of_failure,3,Likelihood_of_failure,3,Automation_status,"Yes"))/C24,1) -> 0 | J24: =IFERROR(if(D20="Release",COUNTIFS(impact_of_failure,2,Likelihood_of_failure,3,Automation_status,"Yes",release,G2),COUNTIFS(impact_of_failure,2,Likelihood_of_failure,3,Automation_status,"Yes"))/D24,1) -> 0 | K24: =IFERROR(if(D20="Release",COUNTIFS(impact_of_failure,1,Likelihood_of_failure,3,Automation_status,"Yes",release,G2),COUNTIFS(impact_of_failure,1,Likelihood_of_failure,3,Automation_status,"Yes"))/E24,1) -> 0.23076923 | M24: Unlikely | N24: =if(instructions!C6=0,"Green",if(I24<instructions!H6,"Red",if(AND(I24>=instructions!H6,I24<instructions!C6),"Amber","Green"))) -> Green | O24: =if(instructions!D6=0,"Green",if(J24<instructions!I6,"Red",if(AND(J24>=instructions!I6,J24<instructions!D6),"Amber","Green"))) -> Green | P24: =if(instructions!E6=0,"Green",if(K24<instructions!J6,"Red",if(AND(K24>=instructions!J6,K24<instructions!E6),"Amber","Green"))) -> Red
B25: Total | C25: =SUM(C22:C24) -> 10 | D25: =SUM(D22:D24) -> 42 | E25: =SUM(E22:E24) -> 55 | F25: =SUM(F22:F24) -> 107
B28: Test execution | D28: Release
C29: Minor | D29: Visible | E29: Interruption | F29: Total | I29: Minor | J29: Visible | K29: Interruption | N29: Minor | O29: Visible | P29: Interruption
B30: Very likely | C30: =IFERROR(if(D28="Release",COUNTIFS(impact_of_failure,3,Likelihood_of_failure,1,status,"Passed",release,G2),COUNTIFS(impact_of_failure,1,Likelihood_of_failure,3,status,"Passed")),0) -> 0 | D30: =IFERROR(if(D28="Release",COUNTIFS(impact_of_failure,2,Likelihood_of_failure,1,status,"Passed",release,G2),COUNTIFS(impact_of_failure,2,Likelihood_of_failure,1,status,"Passed")),0) -> 0 | E30: =IFERROR(if(D28="Release",COUNTIFS(impact_of_failure,1,Likelihood_of_failure,1,status,"Passed",release,G2),COUNTIFS(impact_of_failure,1,Likelihood_of_failure,1,status,"Passed")),0) -> 0 | F30: =SUM(C30:E30) -> 0 | H30: Very likely | I30: =IFERROR(C30/D13,1) -> 1 | J30: =IFERROR(D30/E13,1) -> 1 | K30: =IFERROR(E30/F13,1) -> 1 | M30: Very likely | N30: =if(instructions!C$4=0,"Green",if(I30<instructions!H$4,"Red",if(AND(I30>=instructions!H$4,I30<instructions!C$4),"Amber","Green"))) -> Green | O30: =if(instructions!D$4=0,"Green",if(J30<instructions!I$4,"Red",if(AND(J30>=instructions!I$4,J30<instructions!D$4),"Amber","Green"))) -> Green | P30: =if(instructions!E$4=0,"Green",if(K30<instructions!J$4,"Red",if(AND(K30>=instructions!J$4,K30<instructions!E$4),"Amber","Green"))) -> Green
B31: Quite likely | C31: =IFERROR(if(D28="Release",COUNTIFS(impact_of_failure,3,Likelihood_of_failure,2,status,"Passed",release,G2),COUNTIFS(impact_of_failure,3,Likelihood_of_failure,2,status,"Passed")),0) -> 0 | D31: =IFERROR(if(D28="Release",COUNTIFS(impact_of_failure,2,Likelihood_of_failure,2,status,"Passed",release,G2),COUNTIFS(impact_of_failure,2,Likelihood_of_failure,2,status,"Passed")),0) -> 0 | E31: =IFERROR(if(D28="Release",COUNTIFS(impact_of_failure,1,Likelihood_of_failure,2,status,"Passed",release,G2),COUNTIFS(impact_of_failure,1,Likelihood_of_failure,2,status,"Passed")),0) -> 0 | F31: =SUM(C31:E31) -> 0 | H31: Quite likely | I31: =IFERROR(C31/D14,1) -> 1 | J31: =IFERROR(D31/E14,1) -> 1 | K31: =IFERROR(E31/F14,1) -> 1 | M31: Quite likely | N31: =if(instructions!C$4=0,"Green",if(I31<instructions!H$4,"Red",if(AND(I31>=instructions!H$4,I31<instructions!C$4),"Amber","Green"))) -> Green | O31: =if(instructions!D$4=0,"Green",if(J31<instructions!I$4,"Red",if(AND(J31>=instructions!I$4,J31<instructions!D$4),"Amber","Green"))) -> Green | P31: =if(instructions!E$4=0,"Green",if(K31<instructions!J$4,"Red",if(AND(K31>=instructions!J$4,K31<instructions!E$4),"Amber","Green"))) -> Green
B32: Unlikely | C32: =IFERROR(if(D28="Release",COUNTIFS(impact_of_failure,3,Likelihood_of_failure,3,status,"Passed",release,G2),COUNTIFS(impact_of_failure,3,Likelihood_of_failure,3,status,"Passed")),0) -> 0 | D32: =IFERROR(if(D28="Release",COUNTIFS(impact_of_failure,2,Likelihood_of_failure,3,status,"Passed", release,G2),COUNTIFS(impact_of_failure,2,Likelihood_of_failure,3,status,"Passed")),0) -> 0 | E32: =IFERROR(if(D28="Release",COUNTIFS(impact_of_failure,1,Likelihood_of_failure,3,status,"Passed",release,G2),COUNTIFS(impact_of_failure,1,Likelihood_of_failure,3,status,"Passed")),0) -> 0 | F32: =SUM(C32:E32) -> 0 | H32: Unlikely | I32: =IFERROR(C32/D15,1) -> 1 | J32: =IFERROR(D32/E15,1) -> 1 | K32: =IFERROR(E32/F15,1) -> 1 | M32: Unlikely | N32: =if(instructions!C$4=0,"Green",if(I32<instructions!H$4,"Red",if(AND(I32>=instructions!H$4,I32<instructions!C$4),"Amber","Green"))) -> Green | O32: =if(instructions!D$4=0,"Green",if(J32<instructions!I$4,"Red",if(AND(J32>=instructions!I$4,J32<instructions!D$4),"Amber","Green"))) -> Green | P32: =if(instructions!E$4=0,"Green",if(K32<instructions!J$4,"Red",if(AND(K32>=instructions!J$4,K32<instructions!E$4),"Amber","Green"))) -> Green
B33: Total | C33: =SUM(C30:C32) -> 0 | D33: =SUM(D30:D32) -> 0 | E33: =SUM(E30:E32) -> 0 | F33: =SUM(F30:F32) -> 0
B36: Issue ID | C36: Test cases | D36: competed
B37: =IFERROR(__xludf.DUMMYFUNCTION("FILTER(issue_ID,fixVersion=G2)"),"BAS-1294") -> BAS-1294 | C37: =if(B37="","",COUNTIFS(linked_ID,B37)) -> 0 | D37: =if(B37="","",COUNTIFS(linked_ID,B37,status,"Passed")) -> 0
B38: =IFERROR(__xludf.DUMMYFUNCTION("""COMPUTED_VALUE"""),"BAS-1219") -> BAS-1219 | C38: =if(B38="","",COUNTIFS(linked_ID,B38)) -> 0 | D38: =if(B38="","",COUNTIFS(linked_ID,B38,status,"Passed")) -> 0
B39: =IFERROR(__xludf.DUMMYFUNCTION("""COMPUTED_VALUE"""),"BAS-1166") -> BAS-1166 | C39: =if(B39="","",COUNTIFS(linked_ID,B39)) -> 0 | D39: =if(B39="","",COUNTIFS(linked_ID,B39,status,"Passed")) -> 0
B40: =IFERROR(__xludf.DUMMYFUNCTION("""COMPUTED_VALUE"""),"BAS-1165") -> BAS-1165 | C40: =if(B40="","",COUNTIFS(linked_ID,B40)) -> 0 | D40: =if(B40="","",COUNTIFS(linked_ID,B40,status,"Passed")) -> 0
B41: =IFERROR(__xludf.DUMMYFUNCTION("""COMPUTED_VALUE"""),"BAS-1143") -> BAS-1143 | C41: =if(B41="","",COUNTIFS(linked_ID,B41)) -> 0 | D41: =if(B41="","",COUNTIFS(linked_ID,B41,status,"Passed")) -> 0
B42: =IFERROR(__xludf.DUMMYFUNCTION("""COMPUTED_VALUE"""),"BAS-1092") -> BAS-1092 | C42: =if(B42="","",COUNTIFS(linked_ID,B42)) -> 0
B43: =IFERROR(__xludf.DUMMYFUNCTION("""COMPUTED_VALUE"""),"BAS-1054") -> BAS-1054 | C43: =if(B43="","",COUNTIFS(linked_ID,B43)) -> 0
B44: =IFERROR(__xludf.DUMMYFUNCTION("""COMPUTED_VALUE"""),"BAS-1053") -> BAS-1053 | C44: =if(B44="","",COUNTIFS(linked_ID,B44)) -> 0
B45: =IFERROR(__xludf.DUMMYFUNCTION("""COMPUTED_VALUE"""),"BAS-1050") -> BAS-1050 | C45: =if(B45="","",COUNTIFS(linked_ID,B45)) -> 0
B46: =IFERROR(__xludf.DUMMYFUNCTION("""COMPUTED_VALUE"""),"BAS-1044") -> BAS-1044 | C46: =if(B46="","",COUNTIFS(linked_ID,B46)) -> 0
C47: =if(B47="","",COUNTIFS(linked_ID,B47))
C48: =if(B48="","",COUNTIFS(linked_ID,B48))
C49: =if(B49="","",COUNTIFS(linked_ID,B49))

Sheet Sheet10
B3: Release date | C3: Fix versions | D3: development | E3: tests | F3: bugs
B4: =VLOOKUP(C4,JIRA!$R$2:$U$1000,4,FALSE) -> 45692 | C4: {=UNIQUE(JIRA!R2:R1000)} | D4: =COUNTIFS(JIRA!$R$2:$R$1000,C4) -> 942 | E4: =COUNTIF('testmo-export-repository'!$Y$2:$Y$1000,C4) -> 940 | F4: =COUNTIFS(JIRA!$T$2:$T$1000,C4,JIRA!$A$2:$A$1000,"Bug") -> 25
B5: =VLOOKUP(C5,JIRA!$R$2:$U$1000,4,FALSE) -> 45658 | C5: 2.42 | D5: =COUNTIFS(JIRA!$R$2:$R$1000,C5) -> 3 | E5: =COUNTIF('testmo-export-repository'!$Y$2:$Y$1000,C5) -> 0 | F5: =COUNTIFS(JIRA!$T$2:$T$1000,C5,JIRA!$A$2:$A$1000,"Bug") -> 0
B6: =VLOOKUP(C6,JIRA!$R$2:$U$1000,4,FALSE) -> 45658 | C6: 2.41 | D6: =COUNTIFS(JIRA!$R$2:$R$1000,C6) -> 16 | E6: =COUNTIF('testmo-export-repository'!$Y$2:$Y$1000,C6) -> 0 | F6: =COUNTIFS(JIRA!$T$2:$T$1000,C6,JIRA!$A$2:$A$1000,"Bug") -> 0
B7: =VLOOKUP(C7,JIRA!$R$2:$U$1000,4,FALSE) -> 45667 | C7: 2.41 FE | D7: =COUNTIFS(JIRA!$R$2:$R$1000,C7) -> 10 | E7: =COUNTIF('testmo-export-repository'!$Y$2:$Y$1000,C7) -> 0 | F7: =COUNTIFS(JIRA!$T$2:$T$1000,C7,JIRA!$A$2:$A$1000,"Bug") -> 0
B8: =VLOOKUP(C8,JIRA!$R$2:$U$1000,4,FALSE) -> 45672 | C8: 2.40 | D8: =COUNTIFS(JIRA!$R$2:$R$1000,C8) -> 5 | E8: =COUNTIF('testmo-export-repository'!$Y$2:$Y$1000,C8) -> 0 | F8: =COUNTIFS(JIRA!$T$2:$T$1000,C8,JIRA!$A$2:$A$1000,"Bug") -> 0
B9: =VLOOKUP(C9,JIRA!$R$2:$U$1000,4,FALSE) -> 45674 | C9: 2.38.2 | D9: =COUNTIFS(JIRA!$R$2:$R$1000,C9) -> 1 | E9: =COUNTIF('testmo-export-repository'!$Y$2:$Y$1000,C9) -> 0 | F9: =COUNTIFS(JIRA!$T$2:$T$1000,C9,JIRA!$A$2:$A$1000,"Bug") -> 0
B10: =VLOOKUP(C10,JIRA!$R$2:$U$1000,4,FALSE) -> 45674 | C10: 2.39 | D10: =COUNTIFS(JIRA!$R$2:$R$1000,C10) -> 4 | E10: =COUNTIF('testmo-export-repository'!$Y$2:$Y$1000,C10) -> 7 | F10: =COUNTIFS(JIRA!$T$2:$T$1000,C10,JIRA!$A$2:$A$1000,"Bug") -> 0
B11: =VLOOKUP(C11,JIRA!$R$2:$U$1000,4,FALSE) -> 45692 | C11: 2.38.1 | D11: =COUNTIFS(JIRA!$R$2:$R$1000,C11) -> 1 | E11: =COUNTIF('testmo-export-repository'!$Y$2:$Y$1000,C11) -> 0 | F11: =COUNTIFS(JIRA!$T$2:$T$1000,C11,JIRA!$A$2:$A$1000,"Bug") -> 0
B12: =VLOOKUP(C12,JIRA!$R$2:$U$1000,4,FALSE) -> 45658 | C12: 2.38 | D12: =COUNTIFS(JIRA!$R$2:$R$1000,C12) -> 6 | E12: =COUNTIF('testmo-export-repository'!$Y$2:$Y$1000,C12) -> 27 | F12: =COUNTIFS(JIRA!$T$2:$T$1000,C12,JIRA!$A$2:$A$1000,"Bug") -> 0
B13: =VLOOKUP(C13,JIRA!$R$2:$U$1000,4,FALSE) -> 45658 | C13: 2.37 | D13: =COUNTIFS(JIRA!$R$2:$R$1000,C13) -> 7 | E13: =COUNTIF('testmo-export-repository'!$Y$2:$Y$1000,C13) -> 15 | F13: =COUNTIFS(JIRA!$T$2:$T$1000,C13,JIRA!$A$2:$A$1000,"Bug") -> 3
B14: =VLOOKUP(C14,JIRA!$R$2:$U$1000,4,FALSE) -> 45699 | C14: 2.38;2.39 | D14: =COUNTIFS(JIRA!$R$2:$R$1000,C14) -> 1 | E14: =COUNTIF('testmo-export-repository'!$Y$2:$Y$1000,C14) -> 0 | F14: =COUNTIFS(JIRA!$T$2:$T$1000,C14,JIRA!$A$2:$A$1000,"Bug") -> 0
B15: =VLOOKUP(C15,JIRA!$R$2:$U$1000,4,FALSE) -> 45699 | C15: 2.35.2 | D15: =COUNTIFS(JIRA!$R$2:$R$1000,C15) -> 2 | E15: =COUNTIF('testmo-export-repository'!$Y$2:$Y$1000,C15) -> 0 | F15: =COUNTIFS(JIRA!$T$2:$T$1000,C15,JIRA!$A$2:$A$1000,"Bug") -> 1
B16: =VLOOKUP(C16,JIRA!$R$2:$U$1000,4,FALSE) -> 45692 | C16: 2.36 | D16: =COUNTIFS(JIRA!$R$2:$R$1000,C16) -> 1 | E16: =COUNTIF('testmo-export-repository'!$Y$2:$Y$1000,C16) -> 0 | F16: =COUNTIFS(JIRA!$T$2:$T$1000,C16,JIRA!$A$2:$A$1000,"Bug") -> 2

Sheet testmo-export-repository
A1: ﻿"Case ID" | B1: Case | C1: Configurations | D1: Created at | E1: Created by | F1: Description | G1: Estimate | H1: Expected | I1: Folder | J1: Forecast | K1: Issues | L1: Priority | M1: State | N1: Status (latest) | O1: Status date | P1: Steps (Expected) | Q1: Steps (Step) | R1: Tags | S1: Template | T1: Updated at | U1: Updated by | V1: Automation status | W1: can be automated | X1: complexity | Y1: Release
A2: 1110 | B2: create new datadog metrics so we can set up automated alerts | D2: 2024-04-29T06:40:29.651Z | E2: Matthew East | I2: BAS-474 Create new metrics for reporting on number of files sent | K2: BAS-474 | L2: High | M2: Active | N2: Passed | O2: 2025-01-22T11:08:25.359Z | S2: Gherkin syntax | T2: 2025-01-22T08:28:24.023Z | U2: Matthew East | V2: No | W2: Yes | X2: Low
A3: 2033 | B3: Endpoint for starting feed generation - success | D3: 2024-07-30T08:00:49.587Z | E3: Matthew East | F3: <p>Given: SFG is running<br />and: request json contains gameID <br />and request json contains tracking Path<br />and game took place in last 48 hour window<br />When endpoint put request sent to endpoint<br />Then 200 status is returned<br /><br /><strong>examples</strong></p><figure class="table"><table><tbody><tr><td>request perimeters</td><td>included</td><td>valid</td><td>response</td></tr><tr><td>gameID</td><td>TRUE</td><td>TRUE</td><td>200</td></tr><tr><td>tracking path</td><td>TRUE</td><td>TRUE</td><td>200</td></tr><tr><td>events path</td><td>TRUE</td><td>TRUE</td><td>200</td></tr><tr><td>offset</td><td>TRUE</td><td>TRUE</td><td>200</td></tr><tr><td>force</td><td>FALSE</td><td>n/a</td><td>200</td></tr><tr><td>force</td><td>TRUE</td><td>n/a</td><td>200</td></tr></tbody></table></figure><p><br /> </p><p>endpoint<br />http://localhost:9229/scrubbedFeedGenerator/scrubbed/start</p> | I3: BAS-123 Scrubbed feed generator API | K3: BAS-121 | L3: High | M3: Active | S3: Gherkin syntax | T3: 2025-01-22T08:32:24.903Z | U3: Matthew East | V3: Yes | W3: Yes | X3: Normal
A4: 2034 | B4: request json bad request | D4: 2024-07-30T08:01:17.298Z | E4: Matthew East | F4: <p>Given SFG is running<br />and request json excludes &lt;parameter&gt;<br />and parameter is &lt;valid&gt;<br />when put request is sent to endpoint<br />then status 400 is returned<br /> </p><figure class="table"><table><tbody><tr><td>request permeteres</td><td>included</td><td>valid</td><td>response</td></tr><tr><td>gameID</td><td>FALSE</td><td>N/a</td><td>400</td></tr><tr><td>tracking path</td><td>FALSE</td><td>N/a</td><td>400</td></tr><tr><td>events path</td><td>FALSE</td><td>N/a</td><td>400</td></tr><tr><td>force</td><td>FALSE</td><td>FALSE</td><td>400</td></tr><tr><td>gameID</td><td>TRUE</td><td>FALSE</td><td>400</td></tr><tr><td>tracking path</td><td>TRUE</td><td>FALSE</td><td>400</td></tr><tr><td>events path</td><td>TRUE</td><td>FALSE</td><td>400</td></tr></tbody></table></figure><p><br /><br /><br /> </p> | I4: BAS-123 Scrubbed feed generator API | K4: BAS-121 | L4: Normal | M4: Active | S4: Gherkin syntax | T4: 2025-01-22T08:33:35.113Z | U4: Matthew East | V4: No | W4: No | X4: Normal
A5: 2044 | B5: SFG Scrubbed feeds | D5: 2024-07-30T15:18:29.475Z | E5: Matthew East | F5: <p>Given SFG is running<br />and put request has returned 200 response<br />when SFG reads data from directory<br />Then feed is assembled<br /><br />examples<br />feed<br />processed.pose.clean<br />processed.pose.complete</p> | I5: BAS-125 Assemble scrubbed pose feeds | K5: BAS-121 | L5: High | M5: Active | S5: Gherkin syntax | T5: 2025-01-22T08:34:30.908Z | U5: Matthew East | V5: Yes | W5: Yes | X5: Normal
A6: 2247 | B6: validate feed data processed.pose.clean | D6: 2024-07-31T12:56:45.304Z | E6: Matthew East | I6: BAS-125 Assemble scrubbed pose feeds | L6: High | M6: Active | S6: Gherkin syntax | T6: 2025-01-22T08:34:59.020Z | U6: Matthew East | V6: No | W6: Yes | X6: High
A7: 2248 | B7: validate feed data processed.pose.complete | D7: 2024-07-31T12:57:53.689Z | E7: Matthew East | I7: BAS-125 Assemble scrubbed pose feeds | L7: High | M7: Active | S7: Gherkin syntax | T7: 2025-01-22T08:35:33.654Z | U7: Matthew East | V7: No | W7: Yes | X7: High
A8: 2249 | B8: validate feed data processed.events.complete | D8: 2024-07-31T12:58:06.666Z | E8: Matthew East | I8: BAS-125 Assemble scrubbed pose feeds | L8: High | M8: Active | S8: Gherkin syntax | T8: 2025-01-22T08:35:54.333Z | U8: Matthew East | V8: No | W8: Yes | X8: High
A9: 2250 | B9: validate feed data processed.events.clean | D9: 2024-07-31T12:58:20.542Z | E9: Matthew East | I9: BAS-125 Assemble scrubbed pose feeds | L9: High | M9: Active | S9: Gherkin syntax | T9: 2025-01-22T08:36:21.667Z | U9: Matthew East | V9: No | W9: Yes | X9: High
A10: 2046 | B10: SFG Write feeds to disk | D10: 2024-07-30T15:26:05.246Z | E10: Matthew East | F10: <p>Given SFG is running<br />and put request returns 200 response<br />and output to disk is set in config <br />and assemblers have consumed bson data<br />Then feed is output to disk location </p> | I10: BAS-126 Output scrubbed feeds to disk | K10: BAS-121 | L10: Normal | M10: Active | S10: Gherkin syntax | T10: 2025-01-22T08:36:55.131Z | U10: Matthew East | V10: No | W10: Yes | X10: Normal
A11: 2047 | B11: SFG write to disk false | D11: 2024-07-30T15:31:34.840Z | E11: Matthew East | F11: <p>Given SFG is running<br />and put request returns 200 response<br />and output to disk is set to false in config <br />and assemblers have consumed bson data<br />Then feed is not output disk location</p> | I11: BAS-126 Output scrubbed feeds to disk | L11: Normal | M11: Active | S11: Gherkin syntax | T11: 2025-01-22T08:37:10.692Z | U11: Matthew East | V11: No | W11: Yes | X11: Normal
A12: 2224 | B12: Get and populate game details | D12: 2024-07-31T06:36:10.906Z | E12: Matthew East | F12: <p>Given SFG is running<br />and 200 response returned from endpoint<br />when SFG send get request to NGSS API &lt;endpoint&gt;<br />then data returned is used to populate game details<br /> </p><figure class="table"><table><tbody><tr><td>endpoint</td></tr><tr><td>/leagues/00/seasons?Format=json&amp;limit=0</td></tr><tr><td>/Games/0022301113/officials?Format=json</td></tr><tr><td>/Games/0022301113/rosters?Format=json</td></tr><tr><td>/Games/0022301113?Format=json</td></tr><tr><td>leagues/00/seasons?Format=json&amp;limit=0</td></tr><tr><td>/Games/0022301113/officials?Format=json</td></tr><tr><td>/Games/0022301113/rosters?Format=json</td></tr></tbody></table></figure> | I12: BAS-124 Populate game details from scrubbed API game id | L12: High | M12: Active | S12: Gherkin syntax | T12: 2025-01-22T08:37:39.933Z | U12: Matthew East | V12: No | W12: Yes | X12: High
A13: 7118 | B13: end to end SFG | D13: 2025-01-22T08:38:13.754Z | E13: Matthew East | I13: BAS-122 Setup Scrubbed Feed Generator module | L13: High | M13: Active | S13: Gherkin syntax | T13: 2025-01-22T08:38:29.485Z | U13: Matthew East | V13: No | W13: Yes | X13: High
A14: 2225 | B14: write feed to Azure | D14: 2024-07-31T08:06:28.665Z | E14: Matthew East | F14: <p><strong>Given</strong> SFG is running<br />and put request to start endpoint returned success code<br /><strong>When</strong> data is processed by SFG<br /><strong>Then</strong> feeds are output to Azure<br /><br />feeds.<br />Processed.events.clean<br />Processed.events.complete<br />Processed.pose.clean<br />Processed.pose.ccomplete</p><p><br /> </p> | I14: BAS-127 Output scrubbed feeds to Azure storage | L14: High | M14: Active | S14: Gherkin syntax | T14: 2025-01-22T08:38:46.527Z | U14: Matthew East | V14: No | W14: Yes | X14: High
A15: 2226 | B15: Write feeds to S3 | D15: 2024-07-31T08:34:01.466Z | E15: Matthew East | F15: <p>GIven SFG is running<br />And put request returns success code<br />and SFG has processed feed data<br />Then feeds are output to S3<br /><br />feeds<br /> </p> | I15: BAS-128 Output scrubbed feeds to S3 | L15: High | M15: Active | S15: Gherkin syntax | T15: 2025-01-22T08:39:22.013Z | U15: Matthew East | V15: No | W15: Yes | X15: Normal
A16: 2228 | B16: Get status - queued | D16: 2024-07-31T08:47:18.755Z | E16: Matthew East | F16: <p>Given SFG is running<br />and user has send request to endpoint scrubbed/start<br />When get request sent to endpoint /status<br />Then status "queued" is returned in response </p> | I16: BAS-129 Scrubbed progress metrics | L16: Normal | M16: Active | S16: Gherkin syntax | T16: 2025-01-22T08:40:01.593Z | U16: Matthew East | V16: No | W16: Yes | X16: Normal
A17: 2229 | B17: Get status - in progress | D17: 2024-07-31T09:19:31.874Z | E17: Matthew East | F17: <p>Given SFG is running<br />and scrubbed/batch request has returned status 200 ok<br />when get request is sent to /status endpoint<br />Then status is returned as state "in progress" with timestamp</p> | I17: BAS-129 Scrubbed progress metrics | L17: Normal | M17: Active | S17: Gherkin syntax | T17: 2025-01-22T08:40:16.389Z | U17: Matthew East | V17: No | W17: Yes | X17: Normal
A18: 2231 | B18: get status - finished | D18: 2024-07-31T09:29:46.563Z | E18: Matthew East | F18: <p>Given SFG is running<br />and scrubbed/ batch endpoint has returned code 200<br />and scrubbed/ finish endpoint has returned code 200<br />and all files have have finished processing<br />when get request is sent to endpoint /status<br /><br />Then status is returned state is equal to "finished<br />and started timestamp is true<br />and finished timestamp is true</p> | I18: BAS-129 Scrubbed progress metrics | L18: Normal | M18: Active | S18: Gherkin syntax | T18: 2025-01-22T08:40:35.861Z | U18: Matthew East | V18: No | W18: Yes | X18: Normal
A19: 2230 | B19: scrubbed status - progress 1 | D19: 2024-07-31T09:22:47.309Z | E19: Matthew East | F19: <p>Given SFG is running<br />and scrubbed/ batch endpoint has returned code 200<br />and scrubbed/ finish endpoint has returned code 200<br />and all files have have finished processing<br />when get request is sent to endpoint /status<br />Then progress is returned for &lt;target&gt; &lt;message type&gt; &lt;name&gt; <br />and total should equal attempted <br />and total should equal succeeded<br />and failed should equal 0<br />and skipped should = 0<br /> </p><figure class="table"><table><tbody><tr><td> </td><td>HEI</td><td>NBA</td><td>2S</td><td>Local</td></tr><tr><td>processed.events.complete</td><td>S3</td><td>Azure</td><td> </td><td> </td></tr><tr><td>processed.events.clean</td><td>S3</td><td>Azure</td><td> </td><td> </td></tr><tr><td>processed.pose.complete</td><td>S3</td><td>Azure</td><td>S3</td><td>Disk</td></tr><tr><td>processed.pose.clean</td><td>S3</td><td>Azure</td><td> </td><td>Disk</td></tr></tbody></table></figure> | I19: BAS-129 Scrubbed progress metrics | L19: Normal | M19: Active | S19: Gherkin syntax | T19: 2025-01-22T08:41:06.179Z | U19: Matthew East | V19: Yes | W19: Yes | X19: High
A20: 2240 | B20: silently Ignore frames missing with zero tracking data | D20: 2024-07-31T10:46:54.268Z | E20: Matthew East | F20: <p>Given SFG is running<br />and bson file does not contain &lt;samples&gt;<br />and &lt;gameClock&gt; is equal to false<br />when frame is processed by SFG<br />then error message is no sent to log<br />and counter is incremented by 1<br /><br /> </p><figure class="table"><table><tbody><tr><td> </td><td>Scenario 1</td><td>Scenario 2</td><td>Scenario 3</td><td>Scenario 4</td></tr><tr><td>ballSamples</td><td>Null</td><td>Null</td><td>Null</td><td>Null</td></tr><tr><td>peopleSamples</td><td>Null</td><td>Null</td><td>Null</td><td>Null</td></tr><tr><td>officialsSamples</td><td>Null</td><td>Null</td><td>Null</td><td>Null</td></tr><tr><td>GameClock</td><td>TRUE</td><td>FALSE</td><td>TRUE</td><td>FALSE</td></tr><tr><td>Shotclock</td><td>TRUE</td><td>TRUE</td><td>FALSE</td><td>FALSE</td></tr><tr><td>error message?</td><td>log</td><td>log</td><td>log</td><td>no log</td></tr></tbody></table></figure> | I20: BAS-164 Frames with no tracking data are being reported as errors | L20: Normal | M20: Active | S20: Gherkin syntax | T20: 2025-01-22T08:42:13.693Z | U20: Matthew East | V20: Yes | W20: Yes | X20: High
A21: 2026 | B21: run batch queue game | D21: 2024-07-24T15:39:32.305Z | E21: Matthew East | F21: <p>Given SFG is running<br />and game took place in 48 hour window<br />When put request sent to endpoint scrubbed/stat<br />then status code 200 is returned<br />and game status is queued </p> | I21: BAS-183 Scrubbed chunked uploads | L21: High | M21: Active | S21: Gherkin syntax | T21: 2025-01-22T08:42:44.576Z | U21: Matthew East | V21: Yes | W21: Yes | X21: Normal
A22: 2241 | B22: run batch queue game - bad request | D22: 2024-07-31T12:28:49.496Z | E22: Matthew East | F22: <p>Given SFG is running<br />and game took place in 48 hour window<br />When put request sent to endpoint scrubbed/stat<br />then status code 200 is returned<br />and game status is queued <br /><br /> </p><figure class="table"><table><tbody><tr><td>request permeteres</td><td>included</td><td>valid</td><td>response</td></tr><tr><td>gameID</td><td>FALSE</td><td>N/a</td><td>400</td></tr><tr><td>tracking path</td><td>FALSE</td><td>N/a</td><td>400</td></tr><tr><td>events path</td><td>FALSE</td><td>N/a</td><td>400</td></tr><tr><td>force</td><td>FALSE</td><td>FALSE</td><td>400</td></tr><tr><td>gameID</td><td>TRUE</td><td>FALSE</td><td>400</td></tr><tr><td>tracking path</td><td>TRUE</td><td>FALSE</td><td>400</td></tr><tr><td>events path</td><td>TRUE</td><td>FALSE</td><td>400</td></tr></tbody></table></figure> | I22: BAS-183 Scrubbed chunked uploads | L22: Normal | M22: Active | S22: Gherkin syntax | T22: 2025-01-22T08:43:06.750Z | U22: Matthew East | V22: No | W22: Yes | X22: High
A23: 2242 | B23: run batched upload | D23: 2024-07-31T12:33:12.112Z | E23: Matthew East | F23: <p><strong>Given</strong> SFG is running<br />and game is in queued state<br /><strong>when</strong> put request /batch sent to endpoint<br /><strong>then</strong> status code 200 is returned <br />and all files in directory are processed in SFG<br /><br />request json<br />{</p><p> "gameId": "0022301113", </p><p> "trackingPath": "C:/Users/MatthewEast/work/DataPlatforms/java-backend-automation-pilot/inputData/SFG/BSONS_0022301113_2024-04-050000_HOU_GSW_+500_V11/tracking/1215", </p><p> "trackingEventPath": "C:/Users/MatthewEast/work/DataPlatforms/java-backend-automation-pilot/inputData/SFG/BSONS_0022301113_2024-04-050000_HOU_GSW_+500_V11/events/1215", </p><p> "trackingOffset": "Z"</p><p>}</p> | I23: BAS-183 Scrubbed chunked uploads | L23: High | M23: Active | S23: Gherkin syntax | T23: 2025-01-22T08:43:28.986Z | U23: Matthew East | V23: Yes | W23: Yes | X23: Normal
A24: 2243 | B24: finish batch | D24: 2024-07-31T12:40:45.995Z | E24: Matthew East | I24: BAS-183 Scrubbed chunked uploads | L24: Normal | M24: Active | S24: Case (text)
A25: 2244 | B25: validate order of batch | D25: 2024-07-31T12:42:18.829Z | E25: Matthew East | I25: BAS-183 Scrubbed chunked uploads | L25: High | M25: Active | S25: Gherkin syntax | T25: 2025-01-22T08:43:57.465Z | U25: Matthew East | V25: No | W25: Yes | X25: High
A26: 2245 | B26: Scrubbed chunks - monitoring metrics | D26: 2024-07-31T12:43:33.844Z | E26: Matthew East | I26: BAS-183 Scrubbed chunked uploads | L26: Normal | M26: Active | S26: Gherkin syntax | T26: 2025-01-22T08:44:17.354Z | U26: Matthew East | V26: No | W26: Yes | X26: Normal
